Workbook

Sheet Report1
A1: Column 1 | B1: Column 2 | C1: Column 3 | D1: Column 4 | E1: Column 5 | F1: Column 6 | G1: Call | H1: Schedule | I1: Complete | J1: Column 7 | K1: Column 8 | L1: Column 9
A2: WO# | B2: Prop-Unit | C2: Status | D2: Category | E2: Brief Desc | F2: Tenant | G2: Date | H2: Date | I2: Date | K2: Vendor | L2: Amount
A3: 270 | B3: rheing-533-2C | C3: Work Completed | D3: Plumbing | E3: Bathroom leak/Kitchen faucet | G3: 40064.438 | I3: 40633.801 | J3: =IF(DAYS(I3,G3)<0,0,DAYS(I3,G3)) -> 569 | L3: 0
A4: 272 | B4: rheing-555-6C | C4: Work Completed | D4: Appliances | E4: Refrigerator | G4: 40064.451 | I4: 40633.803 | J4: =IF(DAYS(I4,G4)<0,0,DAYS(I4,G4)) -> 569 | K4: domestic - Domestic Air Conditioning Service, Inc | L4: 0
A5: 273 | B5: rheing-555-6C | C5: Work Completed | D5: Electrical | E5: Kitchen light/ Stove hood fan | G5: 40064.463 | I5: 40633.804 | J5: =IF(DAYS(I5,G5)<0,0,DAYS(I5,G5)) -> 569 | L5: 0
A6: 274 | B6: rheing-533-4J | C6: Work Completed | D6: Painting and Plastering | E6: Painting | G6: 40064.478 | I6: 40633.803 | J6: =IF(DAYS(I6,G6)<0,0,DAYS(I6,G6)) -> 569 | K6: gpspaint - GPS Painting of NY | L6: 0
A7: 275 | B7: rheing-533-5C | C7: Work Completed | D7: Miscellaneous | E7: Intercom | G7: 40064.494 | I7: 40633.803 | J7: =IF(DAYS(I7,G7)<0,0,DAYS(I7,G7)) -> 569 | K7: mgservic - MG Service and Installations, Inc | L7: 0
A8: 276 | B8: rheing-533-4D | C8: Work Completed | D8: Miscellaneous | E8: Bathroom soap dish | G8: 40064.498 | I8: 40633.802 | J8: =IF(DAYS(I8,G8)<0,0,DAYS(I8,G8)) -> 569 | L8: 0
A9: 277 | B9: rheing-555-6I | C9: Work Completed | D9: Flooring | E9: Bathroom tiles/light | G9: 40064.503 | I9: 40634.434 | J9: =IF(DAYS(I9,G9)<0,0,DAYS(I9,G9)) -> 570 | L9: 0
A10: 278 | B10: rheing-555-5A | C10: Work Completed | D10: Miscellaneous | E10: Intercom | G10: 40064.513 | I10: 40633.803 | J10: =IF(DAYS(I10,G10)<0,0,DAYS(I10,G10)) -> 569 | K10: mgservic - MG Service and Installations, Inc | L10: 0
A11: 279 | B11: rheing-555-2C | C11: Work Completed | D11: Appliances | E11: Refrigerator | G11: 40064.6 | I11: 40633.803 | J11: =IF(DAYS(I11,G11)<0,0,DAYS(I11,G11)) -> 569 | L11: 0
A12: 289 | B12: rheing-533-2E | C12: Work Completed | D12: Plumbing | E12: Kitchen sink | G12: 40066.668 | I12: 40106.684 | J12: =IF(DAYS(I12,G12)<0,0,DAYS(I12,G12)) -> 40 | L12: 0
A13: 302 | B13: rheing-555-5C | C13: Work Completed | D13: Extermination | E13: MICE | F13: Morejon,Lucy | G13: 40072.435 | I13: 40085.671 | J13: =IF(DAYS(I13,G13)<0,0,DAYS(I13,G13)) -> 13 | L13: 0
A14: 303 | B14: rheing-533-5B | C14: Work Completed | D14: Plumbing | E14: PLUMBING | F14: Matias,Ramona | G14: 40072.436 | I14: 40085.672 | J14: =IF(DAYS(I14,G14)<0,0,DAYS(I14,G14)) -> 13 | L14: 0
A15: 332 | B15: rheing-533-4F | C15: Work Completed | D15: Plumbing | E15: Bathroom Sink leaking | G15: 40077.401 | I15: 40085.671 | J15: =IF(DAYS(I15,G15)<0,0,DAYS(I15,G15)) -> 8 | K15: mtorres - | L15: 0
A16: 343 | B16: rheing-533-2I | C16: Work Completed | D16: Appliances | E16: Air condition | G16: 40078.646 | I16: 40092.447 | J16: =IF(DAYS(I16,G16)<0,0,DAYS(I16,G16)) -> 14 | L16: 0
A17: 348 | B17: rheing-533-4C | C17: Work Completed | D17: Plumbing | E17: Bathroom | G17: 40079.54 | I17: 40092.465 | J17: =IF(DAYS(I17,G17)<0,0,DAYS(I17,G17)) -> 13 | L17: 0
A18: 354 | B18: rheing-533-4F | C18: Work Completed | D18: Miscellaneous | E18: Bathroom sink | G18: 40079.644 | I18: 40112.628 | J18: =IF(DAYS(I18,G18)<0,0,DAYS(I18,G18)) -> 33 | L18: 0
A19: 414 | B19: rheing-533-4J | C19: Work Completed | D19: Plumbing | E19: Bathroom/bedroom leaks | G19: 40085.531 | I19: 40130.619 | J19: =IF(DAYS(I19,G19)<0,0,DAYS(I19,G19)) -> 45 | L19: 0
A20: 415 | B20: rheing-555-2D | C20: Work Completed | D20: Miscellaneous | E20: Intercom | G20: 40085.551 | I20: 40142.514 | J20: =IF(DAYS(I20,G20)<0,0,DAYS(I20,G20)) -> 57 | L20: 0
A21: 418 | B21: rheing-533-5C | C21: Work Completed | D21: Plumbing | E21: Bathroom Leak | G21: 40085.649 | I21: 40112.629 | J21: =IF(DAYS(I21,G21)<0,0,DAYS(I21,G21)) -> 27 | L21: 0
A22: 427 | B22: rheing-555-5C | C22: Work Completed | D22: Plumbing | E22: Bathroom sink | G22: 40091.456 | I22: 40106.688 | J22: =IF(DAYS(I22,G22)<0,0,DAYS(I22,G22)) -> 15 | L22: 0
A23: 437 | B23: rheing-555-6C | C23: Work Completed | D23: Miscellaneous | E23: Bathroom | G23: 40092.421 | I23: 40106.688 | J23: =IF(DAYS(I23,G23)<0,0,DAYS(I23,G23)) -> 14 | L23: 0
A24: 454 | B24: rheing-533-4E | C24: Work Completed | D24: Heating | E24: Bedroom: heat zone valve | G24: 40095.365 | I24: 40112.629 | J24: =IF(DAYS(I24,G24)<0,0,DAYS(I24,G24)) -> 17 | L24: 0
A25: 465 | B25: rheing-555-6E | C25: Work Completed | D25: Windows | E25: Windows | G25: 40095.644 | I25: 40112.619 | J25: =IF(DAYS(I25,G25)<0,0,DAYS(I25,G25)) -> 17 | L25: 0
A26: 468 | B26: rheing-533-4F | C26: Work Completed | D26: Plumbing | E26: Bathroom Sink | G26: 40095.658 | I26: 40112.628 | J26: =IF(DAYS(I26,G26)<0,0,DAYS(I26,G26)) -> 17 | L26: 0
A27: 475 | B27: rheing-555-5G | C27: Work Completed | D27: Plumbing | E27: Bathroom toilet | G27: 40099.654 | I27: 40112.622 | J27: =IF(DAYS(I27,G27)<0,0,DAYS(I27,G27)) -> 13 | L27: 0
... A38: 530 | B38: rheing-555-3D | C38: Work Completed | D38: Heating | E38: Heat | G38: 40108.676 | I38: 40116.646 | J38: =IF(DAYS(I38,G38)<0,0,DAYS(I38,G38)) -> 8 | L38: 0
A39: 550 | B39: rheing-555-5I | C39: Work Completed | D39: Appliances | E39: REFRIGERATOR | G39: 40113.544 | I39: 40130.619 | J39: =IF(DAYS(I39,G39)<0,0,DAYS(I39,G39)) -> 17 | K39: domestic - Domestic Air Conditioning Service, Inc | L39: 0
A40: 552 | B40: rheing-555-6A | C40: Work Completed | D40: Plumbing | E40: BATHROOM SINK | G40: 40113.56 | I40: 40130.616 | J40: =IF(DAYS(I40,G40)<0,0,DAYS(I40,G40)) -> 17 | L40: 0
A41: 567 | B41: rheing-555-4G | C41: Work Completed | D41: Heating | E41: BROKEN HEATER | G41: 40116.395 | I41: 40253.687 | J41: =IF(DAYS(I41,G41)<0,0,DAYS(I41,G41)) -> 137 | L41: 0
A42: 568 | B42: rheing-533-2G | C42: Work Completed | D42: Doors and Locks | E42: LOCKS / DOORS | G42: 40116.401 | I42: 40126.408 | J42: =IF(DAYS(I42,G42)<0,0,DAYS(I42,G42)) -> 10 | L42: 0
A43: 570 | B43: rheing-555-6A | C43: Work Completed | D43: Miscellaneous | E43: BATHROOM | G43: 40116.502 | I43: 40130.616 | J43: =IF(DAYS(I43,G43)<0,0,DAYS(I43,G43)) -> 14 | L43: 0
A44: 571 | B44: rheing-533-3H | C44: Work Completed | D44: Heating | E44: HEAT | G44: 40116.505 | I44: 40130.618 | J44: =IF(DAYS(I44,G44)<0,0,DAYS(I44,G44)) -> 14 | L44: 0
A45: 572 | B45: rheing-533-2G | C45: Work Completed | D45: Painting and Plastering | E45: LIVINGROOM CEILING | G45: 40116.508 | I45: 40126.398 | J45: =IF(DAYS(I45,G45)<0,0,DAYS(I45,G45)) -> 10 | L45: 0
A46: 578 | B46: rheing-555-5C | C46: Work Completed | D46: Painting and Plastering | E46: KITCHEN WALL | G46: 40116.674 | I46: 40130.617 | J46: =IF(DAYS(I46,G46)<0,0,DAYS(I46,G46)) -> 14 | L46: 0
A47: 596 | B47: rheing-533-2B | C47: Work Completed | D47: Plumbing | E47: Leaking | G47: 40123.668 | I47: 40253.688 | J47: =IF(DAYS(I47,G47)<0,0,DAYS(I47,G47)) -> 130 | L47: 0
A48: 605 | B48: rheing-533-2B | C48: Work Completed | D48: Plumbing | E48: LEAK | F48: Mero,Martha | G48: 40127.416 | I48: 40253.688 | J48: =IF(DAYS(I48,G48)<0,0,DAYS(I48,G48)) -> 126 | L48: 0
A49: 618 | B49: rheing-533-2B | C49: Work Completed | D49: Plumbing | E49: leak | F49: Mero,Martha | G49: 40130.659 | I49: 40142.515 | J49: =IF(DAYS(I49,G49)<0,0,DAYS(I49,G49)) -> 12 | L49: 0
A50: 650 | B50: rheing-555-2D | C50: Work Completed | D50: Plumbing | E50: TOILET | G50: 40134.72 | I50: 40142.515 | J50: =IF(DAYS(I50,G50)<0,0,DAYS(I50,G50)) -> 8 | L50: 0
...

Sheet Categories
A1: Category | B1: Orders Filed | C1: Cost | D1: Orders Completed | E1: Percent Completed | F1: Average TTC
A2: {=UNIQUE(Report1!D3:D6181)} -> Plumbing | B2: =COUNTIF(Report1!D:D,A2) -> 2087 | C2: =AVERAGEIFS(Report1!L:L,Report1!L:L,">0",Report1!D:D,A2) -> 161.04019 | D2: =COUNTIFS(Report1!I:I,">0",Report1!D:D,A2) -> 1948 | E2: =D2/B2 -> 0.93339722 | F2: =AVERAGEIFS(Report1!J:J,Report1!I:I,">0",Report1!D:D,A2) -> 71.638604
A3: Appliances | B3: =COUNTIF(Report1!D:D,A3) -> 341 | C3: =AVERAGEIFS(Report1!L:L,Report1!L:L,">0",Report1!D:D,A3) -> 157.73574 | D3: =COUNTIFS(Report1!I:I,">0",Report1!D:D,A3) -> 294 | E3: =D3/B3 -> 0.86217009 | F3: =AVERAGEIFS(Report1!J:J,Report1!I:I,">0",Report1!D:D,A3) -> 461.96939
A4: Electrical | B4: =COUNTIF(Report1!D:D,A4) -> 506 | C4: =AVERAGEIFS(Report1!L:L,Report1!L:L,">0",Report1!D:D,A4) -> 876.36111 | D4: =COUNTIFS(Report1!I:I,">0",Report1!D:D,A4) -> 469 | E4: =D4/B4 -> 0.92687747 | F4: =AVERAGEIFS(Report1!J:J,Report1!I:I,">0",Report1!D:D,A4) -> 73.599147
A5: Painting and Plastering | B5: =COUNTIF(Report1!D:D,A5) -> 220 | C5: =AVERAGEIFS(Report1!L:L,Report1!L:L,">0",Report1!D:D,A5) -> 133.11154 | D5: =COUNTIFS(Report1!I:I,">0",Report1!D:D,A5) -> 172 | E5: =D5/B5 -> 0.78181818 | F5: =AVERAGEIFS(Report1!J:J,Report1!I:I,">0",Report1!D:D,A5) -> 214.58721
A6: Miscellaneous | B6: =COUNTIF(Report1!D:D,A6) -> 37 | C6: =AVERAGEIFS(Report1!L:L,Report1!L:L,">0",Report1!D:D,A6) -> #DIV/0! | D6: =COUNTIFS(Report1!I:I,">0",Report1!D:D,A6) -> 37 | E6: =D6/B6 -> 1 | F6: =AVERAGEIFS(Report1!J:J,Report1!I:I,">0",Report1!D:D,A6) -> 178
A7: Flooring | B7: =COUNTIF(Report1!D:D,A7) -> 83 | C7: =AVERAGEIFS(Report1!L:L,Report1!L:L,">0",Report1!D:D,A7) -> 2.42 | D7: =COUNTIFS(Report1!I:I,">0",Report1!D:D,A7) -> 62 | E7: =D7/B7 -> 0.74698795 | F7: =AVERAGEIFS(Report1!J:J,Report1!I:I,">0",Report1!D:D,A7) -> 220.67742
A8: Extermination | B8: =COUNTIF(Report1!D:D,A8) -> 147 | C8: =AVERAGEIFS(Report1!L:L,Report1!L:L,">0",Report1!D:D,A8) -> 1067.63 | D8: =COUNTIFS(Report1!I:I,">0",Report1!D:D,A8) -> 115 | E8: =D8/B8 -> 0.78231293 | F8: =AVERAGEIFS(Report1!J:J,Report1!I:I,">0",Report1!D:D,A8) -> 303.89565
A9: Heating | B9: =COUNTIF(Report1!D:D,A9) -> 215 | C9: =AVERAGEIFS(Report1!L:L,Report1!L:L,">0",Report1!D:D,A9) -> 711.6995 | D9: =COUNTIFS(Report1!I:I,">0",Report1!D:D,A9) -> 199 | E9: =D9/B9 -> 0.9255814 | F9: =AVERAGEIFS(Report1!J:J,Report1!I:I,">0",Report1!D:D,A9) -> 152.13568
A10: Windows | B10: =COUNTIF(Report1!D:D,A10) -> 297 | C10: =AVERAGEIFS(Report1!L:L,Report1!L:L,">0",Report1!D:D,A10) -> 2.4671429 | D10: =COUNTIFS(Report1!I:I,">0",Report1!D:D,A10) -> 271 | E10: =D10/B10 -> 0.91245791 | F10: =AVERAGEIFS(Report1!J:J,Report1!I:I,">0",Report1!D:D,A10) -> 713.631
A11: Doors and Locks | B11: =COUNTIF(Report1!D:D,A11) -> 432 | C11: =AVERAGEIFS(Report1!L:L,Report1!L:L,">0",Report1!D:D,A11) -> 183.372 | D11: =COUNTIFS(Report1!I:I,">0",Report1!D:D,A11) -> 372 | E11: =D11/B11 -> 0.86111111 | F11: =AVERAGEIFS(Report1!J:J,Report1!I:I,">0",Report1!D:D,A11) -> 189.72043
A12: Carpentry | B12: =COUNTIF(Report1!D:D,A12) -> 327 | C12: =AVERAGEIFS(Report1!L:L,Report1!L:L,">0",Report1!D:D,A12) -> 3.4225 | D12: =COUNTIFS(Report1!I:I,">0",Report1!D:D,A12) -> 283 | E12: =D12/B12 -> 0.86544343 | F12: =AVERAGEIFS(Report1!J:J,Report1!I:I,">0",Report1!D:D,A12) -> 209.82332
A13: Inspection | B13: =COUNTIF(Report1!D:D,A13) -> 46 | C13: =AVERAGEIFS(Report1!L:L,Report1!L:L,">0",Report1!D:D,A13) -> #DIV/0! | D13: =COUNTIFS(Report1!I:I,">0",Report1!D:D,A13) -> 45 | E13: =D13/B13 -> 0.97826087 | F13: =AVERAGEIFS(Report1!J:J,Report1!I:I,">0",Report1!D:D,A13) -> 37.244444
A14: Boiler | B14: =COUNTIF(Report1!D:D,A14) -> 240 | C14: =AVERAGEIFS(Report1!L:L,Report1!L:L,">0",Report1!D:D,A14) -> 392.01303 | D14: =COUNTIFS(Report1!I:I,">0",Report1!D:D,A14) -> 233 | E14: =D14/B14 -> 0.97083333 | F14: =AVERAGEIFS(Report1!J:J,Report1!I:I,">0",Report1!D:D,A14) -> 672.65236
... A33: Cleaning/Maintenance Supplies | B33: =COUNTIF(Report1!D:D,A33) -> 2 | C33: =AVERAGEIFS(Report1!L:L,Report1!L:L,">0",Report1!D:D,A33) -> #DIV/0! | D33: =COUNTIFS(Report1!I:I,">0",Report1!D:D,A33) -> 2 | E33: =D33/B33 -> 1 | F33: =AVERAGEIFS(Report1!J:J,Report1!I:I,">0",Report1!D:D,A33) -> 144

Sheet Contractors
A1: Biggest | B1: Num Contracts | C1: Avg Value | D1: Total Value | E1: Column 1
A2: rbhvacrp - 1-RBHVACRP- RBMC HVAC REPAIR | B2: 95 | C2: 454.37211 | D2: 43165.35
A3: wtorres - William Torres | B3: 134 | C3: 233.67545 | D3: 31312.51
A4: rbhvaccm - 2-BMC HVAC Contract Maintenance | B4: 18 | C4: 619.525 | D4: 11151.45
A5: riteawaypest - Rite A Way Pest Control Inc | B5: 3 | C5: 2920.6667 | D5: 8762
A6: rheing - Rheingold Gardens Apartments, L.P. | B6: 2123 | C6: 2.5949364 | D6: 5509.05
A7: aaaplaza - Triple A Plaza, LLC | B7: 113 | C7: 39.682035 | D7: 4484.07
A8: hightec - Hi-Tech Heating Corp dba Hi-Tech Heating & Cooling | B8: 51 | C8: 81.389608 | D8: 4150.87
A9: wipeout - Wipeout Exterminating LLC | B9: 30 | C9: 98.931 | D9: 2967.93
A10: safetybuild - Safety Building Cleaning Corp | B10: 2 | C10: 837.5 | D10: 1675
A11: mgservic - MG Service and Installations, Inc | B11: 45 | C11: 36.58 | D11: 1646.1
A12: universa - Universal Fireproof Door Co., Inc. | B12: 4 | C12: 341.25 | D12: 1365
A13: abco - ABCO - LONG ISLAND CITY BRANCH | B13: 2 | C13: 585 | D13: 1170
... A16: ferguson - Ferguson Enterprises, Inc | B16: 2 | C16: 405 | D16: 810
A17: rbmc - Ridgewood Bushwick Management Corp | B17: 1761 | C17: 0.43838728 | D17: 772 | E17: -Internal
A18: heights1 - Rheingold Heights One Associates L.P. | B18: 1 | C18: 674.96 | D18: 674.96 | E18: -Internal
A19: newimper - New Imperial Construction Inc. | B19: 1 | C19: 320 | D19: 320
A20: abovebey - ABOVE & BEYOND PLUMBING & HEATING Corp | B20: 23 | C20: 10.026087 | D20: 230.6
A21: rbmc2 - RiseBoro Management Corporation | B21: 288 | C21: 0.78381944 | D21: 225.74
A22: pride - PRIDE & SERVICE ELEVATOR CO., INC. | B22: 14 | C22: 12.372857 | D22: 173.22
A23: mngreenmai - M&N Green Maintenance LLC | B23: 9 | C23: 5.2222222 | D23: 47
A24: rgs - RG'S Janitorial & Home Improvement Inc. | B24: 27 | C24: 1.7325926 | D24: 46.78
A25: roofservices - Roof Services of NY a Tecta American Company | B25: 2 | C25: 22.025 | D25: 44.05
A26: bigapfir - Big Apple Fire Sprinkler Co., Inc. | B26: 9 | C26: 2.8144444 | D26: 25.33
A27: 135rb - RB 135th Avenue Owner LLC | B27: 1 | C27: 22 | D27: 22
A28: bnh - BNH Lead Examiner Corp. | B28: 11 | C28: 2 | D28: 22
A29: samthegl - Sam The Glazier Corp. | B29: 95 | C29: 0.17126316 | D29: 16.27
A30: gpscon - GPS CONSTRUCTION INC | B30: 19 | C30: 0.85526316 | D30: 16.25
... A95: libertypest - Liberty Pest Control | B95: 1 | C95: 0 | D95: 0

Sheet Copy of Report1
A1: Category | B1: Prop-Unit | C1: Status | D1: Brief Desc | E1: Tenant | F1: Call | G1: Schedule | H1: Complete | I1: Vendor | J1: Amount
A2: Plumbing | B2: rheing-533-2C | C2: Work Completed | D2: Bathroom leak/Kitchen faucet | F2: 40064.438 | H2: 40633.801 | J2: 0
A3: Appliances | B3: rheing-555-6C | C3: Work Completed | D3: Refrigerator | F3: 40064.451 | H3: 40633.803 | I3: domestic - Domestic Air Conditioning Service, Inc | J3: 0
A4: Electrical | B4: rheing-555-6C | C4: Work Completed | D4: Kitchen light/ Stove hood fan | F4: 40064.463 | H4: 40633.804 | J4: 0
A5: Painting and Plastering | B5: rheing-533-4J | C5: Work Completed | D5: Painting | F5: 40064.478 | H5: 40633.803 | I5: gpspaint - GPS Painting of NY | J5: 0
A6: Miscellaneous | B6: rheing-533-5C | C6: Work Completed | D6: Intercom | F6: 40064.494 | H6: 40633.803 | I6: mgservic - MG Service and Installations, Inc | J6: 0
A7: Miscellaneous | B7: rheing-533-4D | C7: Work Completed | D7: Bathroom soap dish | F7: 40064.498 | H7: 40633.802 | J7: 0
A8: Flooring | B8: rheing-555-6I | C8: Work Completed | D8: Bathroom tiles/light | F8: 40064.503 | H8: 40634.434 | J8: 0
A9: Miscellaneous | B9: rheing-555-5A | C9: Work Completed | D9: Intercom | F9: 40064.513 | H9: 40633.803 | I9: mgservic - MG Service and Installations, Inc | J9: 0
A10: Appliances | B10: rheing-555-2C | C10: Work Completed | D10: Refrigerator | F10: 40064.6 | H10: 40633.803 | J10: 0
A11: Plumbing | B11: rheing-533-2E | C11: Work Completed | D11: Kitchen sink | F11: 40066.668 | H11: 40106.684 | J11: 0
A12: Exterminating | B12: rheing-555-5C | C12: Work Completed | D12: MICE | E12: Morejon,Lucy | F12: 40072.435 | H12: 40085.671 | J12: 0
A13: Plumbing | B13: rheing-533-5B | C13: Work Completed | D13: PLUMBING | E13: Matias,Ramona | F13: 40072.436 | H13: 40085.672 | J13: 0
A14: Plumbing | B14: rheing-533-4F | C14: Work Completed | D14: Bathroom Sink leaking | F14: 40077.401 | H14: 40085.671 | I14: mtorres - | J14: 0
A15: Appliances | B15: rheing-533-2I | C15: Work Completed | D15: Air condition | F15: 40078.646 | H15: 40092.447 | J15: 0
A16: Plumbing | B16: rheing-533-4C | C16: Work Completed | D16: Bathroom | F16: 40079.54 | H16: 40092.465 | J16: 0
A17: Miscellaneous | B17: rheing-533-4F | C17: Work Completed | D17: Bathroom sink | F17: 40079.644 | H17: 40112.628 | J17: 0
A18: Plumbing | B18: rheing-533-4J | C18: Work Completed | D18: Bathroom/bedroom leaks | F18: 40085.531 | H18: 40130.619 | J18: 0
A19: Miscellaneous | B19: rheing-555-2D | C19: Work Completed | D19: Intercom | F19: 40085.551 | H19: 40142.514 | J19: 0
A20: Plumbing | B20: rheing-533-5C | C20: Work Completed | D20: Bathroom Leak | F20: 40085.649 | H20: 40112.629 | J20: 0
A21: Plumbing | B21: rheing-555-5C | C21: Work Completed | D21: Bathroom sink | F21: 40091.456 | H21: 40106.688 | J21: 0
A22: Miscellaneous | B22: rheing-555-6C | C22: Work Completed | D22: Bathroom | F22: 40092.421 | H22: 40106.688 | J22: 0
A23: Heating | B23: rheing-533-4E | C23: Work Completed | D23: Bedroom: heat zone valve | F23: 40095.365 | H23: 40112.629 | J23: 0
A24: Windows | B24: rheing-555-6E | C24: Work Completed | D24: Windows | F24: 40095.644 | H24: 40112.619 | J24: 0
A25: Plumbing | B25: rheing-533-4F | C25: Work Completed | D25: Bathroom Sink | F25: 40095.658 | H25: 40112.628 | J25: 0
A26: Plumbing | B26: rheing-555-5G | C26: Work Completed | D26: Bathroom toilet | F26: 40099.654 | H26: 40112.622 | J26: 0
... A37: Heating | B37: rheing-555-3D | C37: Work Completed | D37: Heat | F37: 40108.676 | H37: 40116.646 | J37: 0
A38: Appliances | B38: rheing-555-5I | C38: Work Completed | D38: REFRIGERATOR | F38: 40113.544 | H38: 40130.619 | I38: domestic - Domestic Air Conditioning Service, Inc | J38: 0
A39: Plumbing | B39: rheing-555-6A | C39: Work Completed | D39: BATHROOM SINK | F39: 40113.56 | H39: 40130.616 | J39: 0
A40: Heating | B40: rheing-555-4G | C40: Work Completed | D40: BROKEN HEATER | F40: 40116.395 | H40: 40253.687 | J40: 0
A41: Doors and Locks | B41: rheing-533-2G | C41: Work Completed | D41: LOCKS / DOORS | F41: 40116.401 | H41: 40126.408 | J41: 0
A42: Miscellaneous | B42: rheing-555-6A | C42: Work Completed | D42: BATHROOM | F42: 40116.502 | H42: 40130.616 | J42: 0
A43: Heating | B43: rheing-533-3H | C43: Work Completed | D43: HEAT | F43: 40116.505 | H43: 40130.618 | J43: 0
A44: Painting and Plastering | B44: rheing-533-2G | C44: Work Completed | D44: LIVINGROOM CEILING | F44: 40116.508 | H44: 40126.398 | J44: 0
A45: Painting and Plastering | B45: rheing-555-5C | C45: Work Completed | D45: KITCHEN WALL | F45: 40116.674 | H45: 40130.617 | J45: 0
A46: Plumbing | B46: rheing-533-2B | C46: Work Completed | D46: Leaking | F46: 40123.668 | H46: 40253.688 | J46: 0
A47: Plumbing | B47: rheing-533-2B | C47: Work Completed | D47: LEAK | E47: Mero,Martha | F47: 40127.416 | H47: 40253.688 | J47: 0
B48: rheing-533-2B | C48: Work Completed | D48: leak | E48: Mero,Martha | F48: 40130.659 | H48: 40142.515 | J48: 0
A49: Plumbing | B49: rheing-555-2D | C49: Work Completed | D49: TOILET | F49: 40134.72 | H49: 40142.515 | J49: 0
A50: Plumbing | B50: rheing-533-6J | C50: Work Completed | D50: Bathroom sink | F50: 40135.456 | H50: 40142.516 | J50: 0
...

Sheet Pivot
A1: Column 1 | B1: Column 2 | C1: Column 3 | D1: Column 4 | E1: Column 5 | F1: Column 6 | G1: Call | H1: Schedule | I1: Complete | J1: Column 7 | K1: Column 8
A2: WO# | B2: Prop-Unit | C2: Status | D2: Category | E2: Brief Desc | F2: Tenant | G2: Date | H2: Date | I2: Date | J2: Vendor | K2: Amount
A3: 91271 | B3: rheing | C3: Work Completed | D3: Inspections | E3: 555/533 Bushwick General maintenanc | G3: 45392.661 | I3: 46051.549 | K3: 15795.28
A4: 96384 | B4: rheing | C4: Work Completed | D4: Extermination | E4: 533 ELIMINATE RODENT INFESTATION | G4: 45646.5 | I4: 45681.364 | J4: riteawaypest - Rite A Way Pest Control Inc | K4: 8761
A5: 39278 | B5: rheing | C5: Work Completed | D5: HVAC | E5: 555- Add split system | G5: 42744.664 | I5: 42791.551 | J5: wtorres - William Torres | K5: 8347.51
A6: 80660 | B6: rheing-533-2G | C6: Work Completed | D6: Heating | E6: 533 Heat Equipmt No Cover | G6: 44883.377 | I6: 45013.469 | K6: 8040.71
A7: 45243 | B7: rheing | C7: Work Completed | D7: Electrical | E7: New Electrical for HR Offices | G7: 43012.743 | I7: 43028.478 | J7: rbhvaccm - 2-BMC HVAC Contract Maintenance | K7: 3780
A8: 34879 | B8: rheing-533COMM | C8: Work Completed | D8: Lighting | E8: 555- Basement staorage Lighting | G8: 42562.614 | I8: 42636.504 | J8: wtorres - William Torres | K8: 3255
A9: 64629 | B9: rheing-533-5F | C9: Work Completed | D9: Extermination | E9: bed bug infestation | G9: 43895.343 | I9: 44498.981 | J9: wipeout - Wipeout Exterminating LLC | K9: 2962.68
A10: 79307 | B10: rheing | C10: Work Completed | D10: HVAC | E10: flood | G10: 44793.339 | I10: 44910.435 | J10: hightec - Hi-Tech Heating Corp dba Hi-Tech Heating & Cooling | K10: 2810.32
A11: 42029 | B11: rheing | C11: Work Completed | D11: Plumbing | E11: leak in bathroom | G11: 42866.4 | I11: 42872.5 | J11: rbhvacrp - 1-RBHVACRP- RBMC HVAC REPAIR | K11: 2340
A12: 72430 | B12: rheing-555-3E | C12: Work Completed | D12: Appliances | E12: oven igniter | G12: 44384.338 | I12: 45054.592 | J12: aaaplaza - Triple A Plaza, LLC | K12: 2310.2
A13: 47202 | B13: rheing | C13: Work Completed | D13: Boiler | E13: No Heat Complaints | G13: 43103.52 | I13: 43118.508 | J13: rbhvacrp - 1-RBHVACRP- RBMC HVAC REPAIR | K13: 2040
A14: 80095 | B14: rheing-533-2G | C14: Work Completed | D14: Appliances | E14: 533 Stove / Fridge | G14: 44845.42 | I14: 45006.526 | J14: rheing - Rheingold Gardens Apartments, L.P. | K14: 1990.16
A15: 41432 | B15: rheing-555-6I | C15: Work Completed | D15: Plumbing | E15: 555- leak coming from Tenant shower | G15: 42844.626 | I15: 42870.627 | J15: rbhvacrp - 1-RBHVACRP- RBMC HVAC REPAIR | K15: 1980
A16: 81068 | B16: rheing-555-4C | C16: Work Completed | D16: Appliances | E16: oven | G16: 44910.448 | I16: 45037.541 | J16: aaaplaza - Triple A Plaza, LLC | K16: 1946.02
A17: 34799 | B17: rheing | C17: Work Completed | D17: HVAC | E17: 533 A/C Nurses department | G17: 42559.487 | I17: 42615.457 | J17: wtorres - William Torres | K17: 1710
A18: 107076 | B18: rheing | C18: Work Completed | D18: Painting and Plastering | E18: Mold Removal, Surface Prep, Paint, | G18: 46129.639 | I18: 46129.639 | J18: safetybuild - Safety Building Cleaning Corp | K18: 1675
... A56: 69652 | B56: rheing | C56: Work Completed | D56: Boiler | E56: combustion air fan | G56: 44217.535 | I56: 44463.608 | J56: rbhvacrp - 1-RBHVACRP- RBMC HVAC REPAIR | K56: 682.5
A57: 83666 | B57: rheing-555-6E | C57: Work Completed | D57: Laundry | E57: Hello! Our washers and dryers have | F57: Perez,Elizabeth | G57: 45030.508 | I57: 46106.527 | J57: heights1 - Rheingold Heights One Associates L.P. | K57: 674.96
A58: 61944 | B58: rheing | C58: Work Completed | D58: Boiler | E58: no hot water dhw boiler down | G58: 43756.351 | I58: 43759.414 | J58: rbhvacrp - 1-RBHVACRP- RBMC HVAC REPAIR | K58: 656.25
A59: 36047 | B59: rheing | C59: Work Completed | D59: HVAC | E59: 533-HC-2 - A/C down | G59: 42611.417 | I59: 42613.746 | J59: wtorres - William Torres | K59: 630
A60: 37222 | B60: rheing-533COMM | C60: Work Completed | D60: Electrical | E60: 555- IT Electrical Outlets | G60: 42654.514 | I60: 42663.733 | J60: wtorres - William Torres | K60: 630
A61: 59764 | B61: rheing | C61: Work Completed | D61: HVAC | E61: Ac's in lobby not working | G61: 43654.474 | I61: 43661.387 | J61: rbhvacrp - 1-RBHVACRP- RBMC HVAC REPAIR | K61: 630
A62: 70784 | B62: rheing | C62: Work Completed | D62: Boiler | E62: 2021 Boiler Cleaning | G62: 44286.476 | I62: 44484.537 | J62: rbhvaccm - 2-BMC HVAC Contract Maintenance | K62: 563.85
A63: 33293 | B63: rheing | C63: Work Completed | D63: Plumbing | E63: leak in second floor | G63: 42488.438 | I63: 42530.673 | J63: wtorres - William Torres | K63: 540
A64: 34216 | B64: rheing | C64: Work Completed | D64: HVAC | E64: 533-AC Repair Mr Mathews office | G64: 42531.708 | I64: 42585.676 | J64: wtorres - William Torres | K64: 540
A65: 34217 | B65: rheing | C65: Work Completed | D65: HVAC | E65: 533-AC Repair Kathy Moscoso Office | G65: 42531.719 | I65: 42585.679 | J65: wtorres - William Torres | K65: 540
A66: 34361 | B66: rheing | C66: Work Completed | D66: HVAC | E66: 533-Fresh air fan tripping | G66: 42539.716 | I66: 42585.684 | J66: wtorres - William Torres | K66: 540
A67: 37196 | B67: rheing | C67: Work Completed | D67: Boiler | E67: 533- motor # 1 tripping breaker | G67: 42654.402 | I67: 42664.763 | J67: wtorres - William Torres | K67: 540
A68: 38865 | B68: rheing-533COMM | C68: Work Completed | D68: Heating | E68: Thermostat adjustmments | G68: 42720.562 | I68: 42766.674 | J68: wtorres - William Torres | K68: 540
A69: 39174 | B69: rheing | C69: Work Completed | D69: HVAC | E69: Server Room AC down | G69: 42739.484 | I69: 42766.448 | J69: wtorres - William Torres | K69: 540
... A122: 39690 | B122: rheing | C122: Work Completed | D122: HVAC | E122: 555- Server room AC down | G122: 42762.473 | I122: 42780.533 | J122: wtorres - William Torres | K122: 270
A123: 42189 | B123: rheing | C123: Work Completed | D123: HVAC | E123: 533- Lobby AC down. | G123: 42873.671 | H123: 42874.296 | I123: 42935.544 | J123: rbhvacrp - 1-RBHVACRP- RBMC HVAC REPAIR | K123: 270
A124: 46532 | B124: rheing-533COMM | C124: Work Completed | D124: HVAC | E124: Server Room AC Down | G124: 43069.676 | I124: 43126.682 | J124: rbhvacrp - 1-RBHVACRP- RBMC HVAC REPAIR | K124: 270
A125: 54062 | B125: rheing | C125: Work Completed | D125: Boiler | E125: 555-Boiler #3 Pressure valve | G125: 43389.843 | I125: 43452.701 | J125: rbhvacrp - 1-RBHVACRP- RBMC HVAC REPAIR | K125: 270
A126: 54717 | B126: rheing | C126: Work Completed | D126: Boiler | E126: 555-boiler#1- Flow switch | G126: 43419.588 | I126: 43452.699 | J126: rbhvacrp - 1-RBHVACRP- RBMC HVAC REPAIR | K126: 270
A127: 59472 | B127: rheing | C127: Work Completed | D127: HVAC | E127: 2019 AC - Service and Cleaning | G127: 43635.529 | I127: 43637.659 | J127: rbhvaccm - 2-BMC HVAC Contract Maintenance | K127: 270
A128: 59473 | B128: rheing-533COMM | C128: Work Completed | D128: HVAC | E128: 2019 AC - Service and Cleaning | G128: 43635.536 | I128: 43637.66 | J128: rbhvaccm - 2-BMC HVAC Contract Maintenance | K128: 270
A129: 81370 | B129: rheing | C129: Work Completed | D129: HVAC | E129: Leak from AC system | G129: 44931.354 | I129: 45017.521 | J129: rbhvacrp - 1-RBHVACRP- RBMC HVAC REPAIR | K129: 270
...

Sheet Sheet1
A1: Prop-Unit | B1: Status | C1: Category | D1: Brief Desc | E1: Tenant | F1: Call | G1: Schedule | H1: Complete | I1: Vendor | J1: Amount
A2: =IFERROR(__xludf.DUMMYFUNCTION("COUNTUNIQUE(Report1!B$3:B$6181)"),95.0) -> 95 | B2: =IFERROR(__xludf.DUMMYFUNCTION("COUNTUNIQUE(Report1!C$3:C$6181)"),7.0) -> 7 | C2: =IFERROR(__xludf.DUMMYFUNCTION("COUNTUNIQUE(Report1!D$3:D$6181)"),32.0) -> 32 | D2: =IFERROR(__xludf.DUMMYFUNCTION("COUNTUNIQUE(Report1!E$3:E$6181)"),4302.0) -> 4302 | E2: =IFERROR(__xludf.DUMMYFUNCTION("COUNTUNIQUE(Report1!F$3:F$6181)"),86.0) -> 86 | F2: =IFERROR(__xludf.DUMMYFUNCTION("COUNTUNIQUE(Report1!G$3:G$6181)"),5995.0) -> 5995 | G2: =IFERROR(__xludf.DUMMYFUNCTION("COUNTUNIQUE(Report1!H$3:H$6181)"),94.0) -> 94 | H2: =IFERROR(__xludf.DUMMYFUNCTION("COUNTUNIQUE(Report1!I$3:I$6181)"),5096.0) -> 5096 | I2: =IFERROR(__xludf.DUMMYFUNCTION("COUNTUNIQUE(Report1!K$3:K$6181)"),94.0) -> 94 | J2: =IFERROR(__xludf.DUMMYFUNCTION("COUNTUNIQUE(Report1!L$3:L$6181)"),152.0) -> 152
